Traceback (most recent call last):
  File "/.local/lib/python3.11/site-packages/urllib3/connection.py", line 198, in _new_conn
    sock = connection.create_connection(
           ^^^^^^^^^^^^^^^^^^^^^^^^^^^^^
  File "/.local/lib/python3.11/site-packages/urllib3/util/connection.py", line 85, in create_connection
    raise err
  File "/.local/lib/python3.11/site-packages/urllib3/util/connection.py", line 73, in create_connection
    sock.connect(sa)
ConnectionRefusedError: [Errno 111] Connection refused

The above exception was the direct cause of the following exception:

Traceback (most recent call last):
  File "/.local/lib/python3.11/site-packages/urllib3/connectionpool.py", line 787, in urlopen
    response = self._make_request(
               ^^^^^^^^^^^^^^^^^^^
  File "/.local/lib/python3.11/site-packages/urllib3/connectionpool.py", line 493, in _make_request
    conn.request(
  File "/.local/lib/python3.11/site-packages/urllib3/connection.py", line 445, in request
    self.endheaders()
  File "/opt/bitnami/python/lib/python3.11/http/client.py", line 1281, in endheaders
    self._send_output(message_body, encode_chunked=encode_chunked)
  File "/opt/bitnami/python/lib/python3.11/http/client.py", line 1041, in _send_output
    self.send(msg)
  File "/opt/bitnami/python/lib/python3.11/http/client.py", line 979, in send
    self.connect()
  File "/.local/lib/python3.11/site-packages/urllib3/connection.py", line 276, in connect
    self.sock = self._new_conn()
                ^^^^^^^^^^^^^^^^
  File "/.local/lib/python3.11/site-packages/urllib3/connection.py", line 213, in _new_conn
    raise NewConnectionError(
urllib3.exceptions.NewConnectionError: <urllib3.connection.HTTPConnection object at 0xffff6e324a90>: Failed to establish a new connection: [Errno 111] Connection refused

The above exception was the direct cause of the following exception:

Traceback (most recent call last):
  File "/.local/lib/python3.11/site-packages/requests/adapters.py", line 667, in send
    resp = conn.urlopen(
           ^^^^^^^^^^^^^
  File "/.local/lib/python3.11/site-packages/urllib3/connectionpool.py", line 871, in urlopen
    return self.urlopen(
           ^^^^^^^^^^^^^
  File "/.local/lib/python3.11/site-packages/urllib3/connectionpool.py", line 871, in urlopen
    return self.urlopen(
           ^^^^^^^^^^^^^
  File "/.local/lib/python3.11/site-packages/urllib3/connectionpool.py", line 871, in urlopen
    return self.urlopen(
           ^^^^^^^^^^^^^
  [Previous line repeated 4 more times]
  File "/.local/lib/python3.11/site-packages/urllib3/connectionpool.py", line 841, in urlopen
    retries = retries.increment(
              ^^^^^^^^^^^^^^^^^^
  File "/.local/lib/python3.11/site-packages/urllib3/util/retry.py", line 519, in increment
    raise MaxRetryError(_pool, url, reason) from reason  # type: ignore[arg-type]
    ^^^^^^^^^^^^^^^^^^^^^^^^^^^^^^^^^^^^^^^^^^^^^^^^^^^
urllib3.exceptions.MaxRetryError: HTTPConnectionPool(host='localhost', port=5050): Max retries exceeded with url: /api/2.0/mlflow/experiments/get-by-name?experiment_name=predictive_maintenance (Caused by NewConnectionError('<urllib3.connection.HTTPConnection object at 0xffff6e324a90>: Failed to establish a new connection: [Errno 111] Connection refused'))

During handling of the above exception, another exception occurred:

Traceback (most recent call last):
  File "/.local/lib/python3.11/site-packages/mlflow/utils/rest_utils.py", line 181, in http_request
    return _get_http_response_with_retries(
           ^^^^^^^^^^^^^^^^^^^^^^^^^^^^^^^^
  File "/.local/lib/python3.11/site-packages/mlflow/utils/request_utils.py", line 237, in _get_http_response_with_retries
    return session.request(method, url, allow_redirects=allow_redirects, **kwargs)
           ^^^^^^^^^^^^^^^^^^^^^^^^^^^^^^^^^^^^^^^^^^^^^^^^^^^^^^^^^^^^^^^^^^^^^^^
  File "/.local/lib/python3.11/site-packages/requests/sessions.py", line 589, in request
    resp = self.send(prep, **send_kwargs)
           ^^^^^^^^^^^^^^^^^^^^^^^^^^^^^^
  File "/.local/lib/python3.11/site-packages/requests/sessions.py", line 703, in send
    r = adapter.send(request, **kwargs)
        ^^^^^^^^^^^^^^^^^^^^^^^^^^^^^^^
  File "/.local/lib/python3.11/site-packages/requests/adapters.py", line 700, in send
    raise ConnectionError(e, request=request)
requests.exceptions.ConnectionError: HTTPConnectionPool(host='localhost', port=5050): Max retries exceeded with url: /api/2.0/mlflow/experiments/get-by-name?experiment_name=predictive_maintenance (Caused by NewConnectionError('<urllib3.connection.HTTPConnection object at 0xffff6e324a90>: Failed to establish a new connection: [Errno 111] Connection refused'))

During handling of the above exception, another exception occurred:

Traceback (most recent call last):
  File "/app/src/model/train_model.py", line 16, in <module>
    mlflow.set_experiment(EXPERIMENT_NAME)
  File "/.local/lib/python3.11/site-packages/mlflow/tracking/fluent.py", line 157, in set_experiment
    experiment = client.get_experiment_by_name(experiment_name)
                 ^^^^^^^^^^^^^^^^^^^^^^^^^^^^^^^^^^^^^^^^^^^^^^
  File "/.local/lib/python3.11/site-packages/mlflow/tracking/client.py", line 1698, in get_experiment_by_name
    return self._tracking_client.get_experiment_by_name(name)
           ^^^^^^^^^^^^^^^^^^^^^^^^^^^^^^^^^^^^^^^^^^^^^^^^^^
  File "/.local/lib/python3.11/site-packages/mlflow/tracking/_tracking_service/client.py", line 586, in get_experiment_by_name
    return self.store.get_experiment_by_name(name)
           ^^^^^^^^^^^^^^^^^^^^^^^^^^^^^^^^^^^^^^^
  File "/.local/lib/python3.11/site-packages/mlflow/store/tracking/rest_store.py", line 641, in get_experiment_by_name
    response_proto = self._call_endpoint(GetExperimentByName, req_body)
                     ^^^^^^^^^^^^^^^^^^^^^^^^^^^^^^^^^^^^^^^^^^^^^^^^^^
  File "/.local/lib/python3.11/site-packages/mlflow/store/tracking/rest_store.py", line 90, in _call_endpoint
    return call_endpoint(self.get_host_creds(), endpoint, method, json_body, response_proto)
           ^^^^^^^^^^^^^^^^^^^^^^^^^^^^^^^^^^^^^^^^^^^^^^^^^^^^^^^^^^^^^^^^^^^^^^^^^^^^^^^^^
  File "/.local/lib/python3.11/site-packages/mlflow/utils/rest_utils.py", line 387, in call_endpoint
    response = http_request(**call_kwargs)
               ^^^^^^^^^^^^^^^^^^^^^^^^^^^
  File "/.local/lib/python3.11/site-packages/mlflow/utils/rest_utils.py", line 204, in http_request
    raise MlflowException(f"API request to {url} failed with exception {e}")
mlflow.exceptions.MlflowException: API request to http://localhost:5050/api/2.0/mlflow/experiments/get-by-name failed with exception HTTPConnectionPool(host='localhost', port=5050): Max retries exceeded with url: /api/2.0/mlflow/experiments/get-by-name?experiment_name=predictive_maintenance (Caused by NewConnectionError('<urllib3.connection.HTTPConnection object at 0xffff6e324a90>: Failed to establish a new connection: [Errno 111] Connection refused'))
